Workbook
Name TableDig: '3.2 Digest'!$1:$1048576

Sheet 1. Information samples
E4: INFORMATION SAMPLES
B10: Sample serial No | C10: Date (M,D.Y) | D10: Requisitioner | E10: Set CIAT | F10: CIAT Lab-ID | G10: Gene bank /Breeding program ID | H10: Genus | I10: Species | J10: Tax Name | K10: Family | L10: Order | M10: Functional Group | N10: Batches CIAT | O10: ID LAB | P10: Observaciones
B11: 1 | C11: 46041 | D11: Genbank | E11: 27 | F11: F251728 | G11: CIAT-13262 | H11: Dendrolobium | I11: triangulare | J11: Dendrolobium triangulare | K11: Fabaceae | L11: Fabales | M11: Tree | N11: 58,59, 69 | O11: OT-010 (2025)
B12: =B11+1 -> 2 | C12: 46041 | D12: Genbank | E12: 27 | F12: F251729 | G12: CIAT-13528 | H12: Dendrolobium | I12: lanceolatum | J12: Dendrolobium lanceolatum | K12: Fabaceae | L12: Fabales | M12: Tree | N12: 58,59, 69 | O12: OT-010 (2025)
B13: =B12+1 -> 3 | C13: 46041 | D13: Genbank | E13: 27 | F13: F251730 | G13: CIAT-13529 | H13: Dendrolobium | I13: triangulare | J13: Dendrolobium triangulare | K13: Fabaceae | L13: Fabales | M13: Tree | N13: 58,59, 69 | O13: OT-010 (2025)
B14: =B13+1 -> 4 | C14: 46041 | D14: Genbank | E14: 27 | F14: F251731 | G14: CIAT-13710 | H14: Dendrolobium | I14: lanceolatum | J14: Dendrolobium lanceolatum | K14: Fabaceae | L14: Fabales | M14: Tree | N14: 58,59, 69 | O14: OT-010 (2025)
B15: =B14+1 -> 5 | C15: 46041 | D15: Genbank | E15: 27 | F15: F251732 | G15: CIAT-22004 | H15: Dendrolobium | I15: triangulare | J15: Dendrolobium triangulare | K15: Fabaceae | L15: Fabales | M15: Tree | N15: 58,59, 69 | O15: OT-010 (2025)
B16: =B15+1 -> 6 | C16: 46041 | D16: Genbank | E16: 27 | F16: F251733 | G16: CIAT-23104 | H16: Dendrolobium | I16: triangulare | J16: Dendrolobium triangulare | K16: Fabaceae | L16: Fabales | M16: Tree | N16: 58,59, 69 | O16: OT-010 (2025)
B17: =B16+1 -> 7 | C17: 46041 | D17: Genbank | E17: 27 | F17: F251734 | G17: CIAT-23106 | H17: Dendrolobium | I17: triangulare | J17: Dendrolobium triangulare | K17: Fabaceae | L17: Fabales | M17: Tree | N17: 58,59, 69 | O17: OT-010 (2025)
B18: =B17+1 -> 8 | C18: 46041 | D18: Genbank | E18: 27 | F18: F251735 | G18: CIAT-23107 | H18: Dendrolobium | I18: triangulare | J18: Dendrolobium triangulare | K18: Fabaceae | L18: Fabales | M18: Tree | N18: 58,59, 69 | O18: OT-010 (2025)
B19: =B18+1 -> 9 | C19: 46041 | D19: Genbank | E19: 27 | F19: F251736 | G19: CIAT-23108 | H19: Dendrolobium | I19: triangulare | J19: Dendrolobium triangulare | K19: Fabaceae | L19: Fabales | M19: Tree | N19: 58,59, 69 | O19: OT-010 (2025)
B20: =B19+1 -> 10 | C20: 46041 | D20: Genbank | E20: 27 | F20: F251737 | G20: CIAT-23412 | H20: Dendrolobium | I20: triangulare | J20: Dendrolobium triangulare | K20: Fabaceae | L20: Fabales | M20: Tree | N20: 58,59, 69 | O20: OT-010 (2025)
B21: =B20+1 -> 11 | C21: 46041 | D21: Genbank | E21: 27 | F21: F251738 | G21: CIAT-23413 | H21: Dendrolobium | I21: triangulare | J21: Dendrolobium triangulare | K21: Fabaceae | L21: Fabales | M21: Tree | N21: 58,59, 69 | O21: OT-010 (2025)
B22: =B21+1 -> 12 | C22: 46041 | D22: Genbank | E22: 27 | F22: F251739 | G22: CIAT-23419 | H22: Dendrolobium | I22: triangulare | J22: Dendrolobium triangulare | K22: Fabaceae | L22: Fabales | M22: Tree | N22: 58,59, 69 | O22: OT-010 (2025)
B23: =B22+1 -> 13 | C23: 46041 | D23: Genbank | E23: 27 | F23: F251740 | G23: CIAT-23422 | H23: Dendrolobium | I23: triangulare | J23: Dendrolobium triangulare | K23: Fabaceae | L23: Fabales | M23: Tree | N23: 58,59, 69 | O23: OT-010 (2025)
... B57: =B56+1 -> 47 | C57: 46048 | D57: Genbank | E57: 28 | F57: F251771 | G57: CIAT-22310 | H57: Calliandra | I57: calothyrsus | J57: Calliandra calothyrsus | K57: Fabaceae | L57: Fabales | M57: Tree | N57: 60,61, 62 | O57: OT-010
B58: =B57+1 -> 48 | C58: 46048 | D58: Genbank | E58: 28 | F58: F251772 | G58: CIAT-22311 | H58: Calliandra | I58: calothyrsus | J58: Calliandra calothyrsus | K58: Fabaceae | L58: Fabales | M58: Tree | N58: 60,61, 62 | O58: OT-010 | P58: Se debera repetir | Q58: Falta
B59: =B58+1 -> 49 | C59: 46048 | D59: Genbank | E59: 28 | F59: F251773 | G59: CIAT-22316 | H59: Calliandra | I59: calothyrsus | J59: Calliandra calothyrsus | K59: Fabaceae | L59: Fabales | M59: Tree | N59: 60,61, 62 | O59: OT-010
B60: =B59+1 -> 50 | C60: 46048 | D60: Genbank | E60: 28 | F60: F251774 | G60: CIAT-23239 | H60: Dendrolobium | I60: triangulare | J60: Dendrolobium triangulare | K60: Fabaceae | L60: Fabales | M60: Tree | N60: 60,61, 62 | O60: OT-010
B61: =B60+1 -> 51 | C61: 46048 | D61: Genbank | E61: 28 | F61: F251775 | G61: CIAT-33116 | H61: Dendrolobium | I61: triangulare | J61: Dendrolobium triangulare | K61: Fabaceae | L61: Fabales | M61: Tree | N61: 60,61, 62 | O61: OT-010
B62: =B61+1 -> 52 | C62: 46048 | D62: Genbank | E62: 28 | F62: F252184 | G62: CIAT-BH22_0303 | H62: Urochloa | I62: humidicola | J62: Urochloa humidicola | K62: Poaceae | L62: Poales | M62: grasses | N62: 60,61, 62 | O62: OT-021 | Q62: Reproceso Joha Set 34
B63: =B62+1 -> 53 | C63: 46048 | D63: Genbank | E63: 28 | F63: F252185 | G63: CIAT-BH22_1594 | H63: Urochloa | I63: humidicola | J63: Urochloa humidicola | K63: Poaceae | L63: Poales | M63: grasses | N63: 60,61, 62 | O63: OT-021
B64: =B63+1 -> 54 | C64: 46048 | D64: Genbank | E64: 28 | F64: F252186 | G64: CIAT-BH22_0468 | H64: Urochloa | I64: humidicola | J64: Urochloa humidicola | K64: Poaceae | L64: Poales | M64: grasses | N64: 60,61, 62 | O64: OT-021
B65: =B64+1 -> 55 | C65: 46048 | D65: Genbank | E65: 28 | F65: F252187 | G65: CIAT-BH22_3830 | H65: Urochloa | I65: humidicola | J65: Urochloa humidicola | K65: Poaceae | L65: Poales | M65: grasses | N65: 60,61, 62 | O65: OT-021
B66: =B65+1 -> 56 | C66: 46048 | D66: Genbank | E66: 28 | F66: F252188 | G66: CIAT-BH22_1710 | H66: Urochloa | I66: humidicola | J66: Urochloa humidicola | K66: Poaceae | L66: Poales | M66: grasses | N66: 60,61, 62 | O66: OT-021
B67: =B66+1 -> 57 | C67: 46048 | D67: Genbank | E67: 28 | F67: F252189 | G67: CIAT-BH22_2365 | H67: Urochloa | I67: humidicola | J67: Urochloa humidicola | K67: Poaceae | L67: Poales | M67: grasses | N67: 60,61, 62 | O67: OT-021
B68: =B67+1 -> 58 | C68: 46048 | D68: Genbank | E68: 28 | F68: F252190 | G68: CIAT-BH22_3572 | H68: Urochloa | I68: humidicola | J68: Urochloa humidicola | K68: Poaceae | L68: Poales | M68: grasses | N68: 60,61, 62 | O68: OT-021
B69: =B68+1 -> 59 | C69: 46048 | D69: Genbank | E69: 28 | F69: F252191 | G69: CIAT-BH22_0517 | H69: Urochloa | I69: humidicola | J69: Urochloa humidicola | K69: Poaceae | L69: Poales | M69: grasses | N69: 60,61, 62 | O69: OT-021 | P69: Se debera repetir | Q69: Reproceso Joha Set 34
B70: =B69+1 -> 60 | C70: 46048 | D70: Genbank | E70: 28 | F70: F252192 | G70: CIAT-BH22_0519 | H70: Urochloa | I70: humidicola | J70: Urochloa humidicola | K70: Poaceae | L70: Poales | M70: grasses | N70: 60,61, 62 | O70: OT-021 | P70: Se debera repetir | Q70: Reproceso Joha Set 34
B71: =B70+1 -> 61 | C71: 46048 | D71: Genbank | E71: 28 | F71: F252193 | G71: CIAT-BH22_0521 | H71: Urochloa | I71: humidicola | J71: Urochloa humidicola | K71: Poaceae | L71: Poales | M71: grasses | N71: 60,61, 62 | O71: OT-021
B72: =B71+1 -> 62 | C72: 46048 | D72: Genbank | E72: 28 | F72: F252574 | G72: CIAT326 | H72: Desmodium | I72: scorpiurus | J72: Desmodium scorpiurus | K72: Fabaceae | L72: Fabales | M72: Herbaceous | N72: 60,61, 62 | O72: OT-031
B73: =B72+1 -> 63 | C73: 46048 | D73: Jacobo Arango/Alejandro Montoya | E73: 28 | F73: F250008 | G73: Sample 8 | H73: Cynodon | I73: nlemfuensis | J73: Cynodon nlemfuensis | K73: Poaceae | L73: Poales | M73: grasses | N73: 60,61, 62 | O73: OT-002
B74: =B73+1 -> 64 | C74: 46048 | D74: Genbank | E74: 28 | F74: F252575 | G74: CIAT415 | H74: Vigna | I74: radiata | J74: Vigna radiata | K74: Fabaceae | L74: Fabales | M74: Herbaceous | N74: 60,61, 62 | O74: OT-031
B75: =B74+1 -> 65 | C75: 46048 | D75: Genbank | E75: 28 | F75: F252576 | G75: CIAT416 | H75: Vigna | I75: radiata | J75: Vigna radiata | K75: Fabaceae | L75: Fabales | M75: Herbaceous | N75: 60,61, 62 | O75: OT-031
B76: =B75+1 -> 66 | C76: 46048 | D76: Genbank | E76: 28 | F76: F252577 | G76: CIAT517 | H76: Macroptilium | I76: atropurpureum | J76: Macroptilium atropurpureum | K76: Fabaceae | L76: Fabales | M76: Herbaceous | N76: 60,61, 62 | O76: OT-031
B77: =B76+1 -> 67 | C77: 46048 | D77: Genbank | E77: 28 | F77: F252578 | G77: CIAT563 | H77: Macroptilium | I77: bracteatum | J77: Macroptilium bracteatum | K77: Fabaceae | L77: Fabales | M77: Herbaceous | N77: 60,61, 62 | O77: OT-031
B78: =B77+1 -> 68 | C78: 46048 | D78: Genbank | E78: 28 | F78: F252579 | G78: CIAT789 | H78: Zornia | I78: latifolia | J78: Zornia latifolia | K78: Fabaceae | L78: Fabales | M78: Herbaceous | N78: 60,61, 62 | O78: OT-031
B79: =B78+1 -> 69 | C79: 46048 | D79: Genbank | E79: 28 | F79: F252580 | G79: CIAT2085 | H79: Stylosanthes | I79: seabrana | J79: Stylosanthes seabrana | K79: Fabaceae | L79: Fabales | M79: Herbaceous | N79: 60,61, 62 | O79: OT-031
B80: =B79+1 -> 70 | C80: 46048 | D80: Genbank | E80: 28 | F80: F252581 | G80: CIAT2690 | H80: Stylosanthes | I80: angustifolia | J80: Stylosanthes angustifolia | K80: Fabaceae | L80: Fabales | M80: Herbaceous | N80: 60,61, 62 | O80: OT-031
B81: =B80+1 -> 71 | C81: 46048 | D81: Genbank | E81: 28 | F81: F252582 | G81: CIAT4069 | H81: Macroptilium | I81: atropurpureum | J81: Macroptilium atropurpureum | K81: Fabaceae | L81: Fabales | M81: Herbaceous | N81: 60,61, 62 | O81: OT-031
...

Sheet 10_information_samples
A1: 10_sample_serial_no | B1: 10_date | C1: 10_requisitioner | D1: 10_set_ciat | E1: 10_ciat_lab_id | F1: 10_gene_bank_breeding_program_id | G1: 10_genus | H1: 10_species | I1: 10_tax_name | J1: 10_family | K1: 10_order | L1: 10_functional_group | M1: 10_batches_ciat | N1: 10_id_lab | O1: 10_remarks_1 | P1: 10_remarks_2
A2: Sample serial No | B2: Date (M,D.Y) | C2: Requisitioner | D2: Set CIAT | E2: CIAT Lab-ID | F2: Gene bank /Breeding program ID | G2: Genus | H2: Species | I2: Tax Name | J2: Family | K2: Order | L2: Functional Group | M2: Batches CIAT | N2: ID LAB | O2: Observaciones
A3: 1 | B3: 46041 | C3: Genbank | D3: 27 | E3: F251728 | F3: CIAT-13262 | G3: Dendrolobium | H3: triangulare | I3: Dendrolobium triangulare | J3: Fabaceae | K3: Fabales | L3: Tree | M3: 58,59, 69 | N3: OT-010 (2025)
A4: 2 | B4: 46041 | C4: Genbank | D4: 27 | E4: F251729 | F4: CIAT-13528 | G4: Dendrolobium | H4: lanceolatum | I4: Dendrolobium lanceolatum | J4: Fabaceae | K4: Fabales | L4: Tree | M4: 58,59, 69 | N4: OT-010 (2025)
A5: 3 | B5: 46041 | C5: Genbank | D5: 27 | E5: F251730 | F5: CIAT-13529 | G5: Dendrolobium | H5: triangulare | I5: Dendrolobium triangulare | J5: Fabaceae | K5: Fabales | L5: Tree | M5: 58,59, 69 | N5: OT-010 (2025)
A6: 4 | B6: 46041 | C6: Genbank | D6: 27 | E6: F251731 | F6: CIAT-13710 | G6: Dendrolobium | H6: lanceolatum | I6: Dendrolobium lanceolatum | J6: Fabaceae | K6: Fabales | L6: Tree | M6: 58,59, 69 | N6: OT-010 (2025)
A7: 5 | B7: 46041 | C7: Genbank | D7: 27 | E7: F251732 | F7: CIAT-22004 | G7: Dendrolobium | H7: triangulare | I7: Dendrolobium triangulare | J7: Fabaceae | K7: Fabales | L7: Tree | M7: 58,59, 69 | N7: OT-010 (2025)
A8: 6 | B8: 46041 | C8: Genbank | D8: 27 | E8: F251733 | F8: CIAT-23104 | G8: Dendrolobium | H8: triangulare | I8: Dendrolobium triangulare | J8: Fabaceae | K8: Fabales | L8: Tree | M8: 58,59, 69 | N8: OT-010 (2025)
A9: 7 | B9: 46041 | C9: Genbank | D9: 27 | E9: F251734 | F9: CIAT-23106 | G9: Dendrolobium | H9: triangulare | I9: Dendrolobium triangulare | J9: Fabaceae | K9: Fabales | L9: Tree | M9: 58,59, 69 | N9: OT-010 (2025)
A10: 8 | B10: 46041 | C10: Genbank | D10: 27 | E10: F251735 | F10: CIAT-23107 | G10: Dendrolobium | H10: triangulare | I10: Dendrolobium triangulare | J10: Fabaceae | K10: Fabales | L10: Tree | M10: 58,59, 69 | N10: OT-010 (2025)
A11: 9 | B11: 46041 | C11: Genbank | D11: 27 | E11: F251736 | F11: CIAT-23108 | G11: Dendrolobium | H11: triangulare | I11: Dendrolobium triangulare | J11: Fabaceae | K11: Fabales | L11: Tree | M11: 58,59, 69 | N11: OT-010 (2025)
A12: 10 | B12: 46041 | C12: Genbank | D12: 27 | E12: F251737 | F12: CIAT-23412 | G12: Dendrolobium | H12: triangulare | I12: Dendrolobium triangulare | J12: Fabaceae | K12: Fabales | L12: Tree | M12: 58,59, 69 | N12: OT-010 (2025)
A13: 11 | B13: 46041 | C13: Genbank | D13: 27 | E13: F251738 | F13: CIAT-23413 | G13: Dendrolobium | H13: triangulare | I13: Dendrolobium triangulare | J13: Fabaceae | K13: Fabales | L13: Tree | M13: 58,59, 69 | N13: OT-010 (2025)
A14: 12 | B14: 46041 | C14: Genbank | D14: 27 | E14: F251739 | F14: CIAT-23419 | G14: Dendrolobium | H14: triangulare | I14: Dendrolobium triangulare | J14: Fabaceae | K14: Fabales | L14: Tree | M14: 58,59, 69 | N14: OT-010 (2025)
... A49: 47 | B49: 46048 | C49: Genbank | D49: 28 | E49: F251771 | F49: CIAT-22310 | G49: Calliandra | H49: calothyrsus | I49: Calliandra calothyrsus | J49: Fabaceae | K49: Fabales | L49: Tree | M49: 60,61, 62 | N49: OT-010
A50: 48 | B50: 46048 | C50: Genbank | D50: 28 | E50: F251772 | F50: CIAT-22311 | G50: Calliandra | H50: calothyrsus | I50: Calliandra calothyrsus | J50: Fabaceae | K50: Fabales | L50: Tree | M50: 60,61, 62 | N50: OT-010 | O50: Se debera repetir | P50: Falta
A51: 49 | B51: 46048 | C51: Genbank | D51: 28 | E51: F251773 | F51: CIAT-22316 | G51: Calliandra | H51: calothyrsus | I51: Calliandra calothyrsus | J51: Fabaceae | K51: Fabales | L51: Tree | M51: 60,61, 62 | N51: OT-010
A52: 50 | B52: 46048 | C52: Genbank | D52: 28 | E52: F251774 | F52: CIAT-23239 | G52: Dendrolobium | H52: triangulare | I52: Dendrolobium triangulare | J52: Fabaceae | K52: Fabales | L52: Tree | M52: 60,61, 62 | N52: OT-010
A53: 51 | B53: 46048 | C53: Genbank | D53: 28 | E53: F251775 | F53: CIAT-33116 | G53: Dendrolobium | H53: triangulare | I53: Dendrolobium triangulare | J53: Fabaceae | K53: Fabales | L53: Tree | M53: 60,61, 62 | N53: OT-010
A54: 52 | B54: 46048 | C54: Genbank | D54: 28 | E54: F252184 | F54: CIAT-BH22_0303 | G54: Urochloa | H54: humidicola | I54: Urochloa humidicola | J54: Poaceae | K54: Poales | L54: grasses | M54: 60,61, 62 | N54: OT-021 | P54: Reproceso Joha Set 34
A55: 53 | B55: 46048 | C55: Genbank | D55: 28 | E55: F252185 | F55: CIAT-BH22_1594 | G55: Urochloa | H55: humidicola | I55: Urochloa humidicola | J55: Poaceae | K55: Poales | L55: grasses | M55: 60,61, 62 | N55: OT-021
A56: 54 | B56: 46048 | C56: Genbank | D56: 28 | E56: F252186 | F56: CIAT-BH22_0468 | G56: Urochloa | H56: humidicola | I56: Urochloa humidicola | J56: Poaceae | K56: Poales | L56: grasses | M56: 60,61, 62 | N56: OT-021
A57: 55 | B57: 46048 | C57: Genbank | D57: 28 | E57: F252187 | F57: CIAT-BH22_3830 | G57: Urochloa | H57: humidicola | I57: Urochloa humidicola | J57: Poaceae | K57: Poales | L57: grasses | M57: 60,61, 62 | N57: OT-021
A58: 56 | B58: 46048 | C58: Genbank | D58: 28 | E58: F252188 | F58: CIAT-BH22_1710 | G58: Urochloa | H58: humidicola | I58: Urochloa humidicola | J58: Poaceae | K58: Poales | L58: grasses | M58: 60,61, 62 | N58: OT-021
A59: 57 | B59: 46048 | C59: Genbank | D59: 28 | E59: F252189 | F59: CIAT-BH22_2365 | G59: Urochloa | H59: humidicola | I59: Urochloa humidicola | J59: Poaceae | K59: Poales | L59: grasses | M59: 60,61, 62 | N59: OT-021
A60: 58 | B60: 46048 | C60: Genbank | D60: 28 | E60: F252190 | F60: CIAT-BH22_3572 | G60: Urochloa | H60: humidicola | I60: Urochloa humidicola | J60: Poaceae | K60: Poales | L60: grasses | M60: 60,61, 62 | N60: OT-021
A61: 59 | B61: 46048 | C61: Genbank | D61: 28 | E61: F252191 | F61: CIAT-BH22_0517 | G61: Urochloa | H61: humidicola | I61: Urochloa humidicola | J61: Poaceae | K61: Poales | L61: grasses | M61: 60,61, 62 | N61: OT-021 | O61: Se debera repetir | P61: Reproceso Joha Set 34
A62: 60 | B62: 46048 | C62: Genbank | D62: 28 | E62: F252192 | F62: CIAT-BH22_0519 | G62: Urochloa | H62: humidicola | I62: Urochloa humidicola | J62: Poaceae | K62: Poales | L62: grasses | M62: 60,61, 62 | N62: OT-021 | O62: Se debera repetir | P62: Reproceso Joha Set 34
A63: 61 | B63: 46048 | C63: Genbank | D63: 28 | E63: F252193 | F63: CIAT-BH22_0521 | G63: Urochloa | H63: humidicola | I63: Urochloa humidicola | J63: Poaceae | K63: Poales | L63: grasses | M63: 60,61, 62 | N63: OT-021
A64: 62 | B64: 46048 | C64: Genbank | D64: 28 | E64: F252574 | F64: CIAT326 | G64: Desmodium | H64: scorpiurus | I64: Desmodium scorpiurus | J64: Fabaceae | K64: Fabales | L64: Herbaceous | M64: 60,61, 62 | N64: OT-031
A65: 63 | B65: 46048 | C65: Jacobo Arango/Alejandro Montoya | D65: 28 | E65: F250008 | F65: Sample 8 | G65: Cynodon | H65: nlemfuensis | I65: Cynodon nlemfuensis | J65: Poaceae | K65: Poales | L65: grasses | M65: 60,61, 62 | N65: OT-002
A66: 64 | B66: 46048 | C66: Genbank | D66: 28 | E66: F252575 | F66: CIAT415 | G66: Vigna | H66: radiata | I66: Vigna radiata | J66: Fabaceae | K66: Fabales | L66: Herbaceous | M66: 60,61, 62 | N66: OT-031
A67: 65 | B67: 46048 | C67: Genbank | D67: 28 | E67: F252576 | F67: CIAT416 | G67: Vigna | H67: radiata | I67: Vigna radiata | J67: Fabaceae | K67: Fabales | L67: Herbaceous | M67: 60,61, 62 | N67: OT-031
A68: 66 | B68: 46048 | C68: Genbank | D68: 28 | E68: F252577 | F68: CIAT517 | G68: Macroptilium | H68: atropurpureum | I68: Macroptilium atropurpureum | J68: Fabaceae | K68: Fabales | L68: Herbaceous | M68: 60,61, 62 | N68: OT-031
A69: 67 | B69: 46048 | C69: Genbank | D69: 28 | E69: F252578 | F69: CIAT563 | G69: Macroptilium | H69: bracteatum | I69: Macroptilium bracteatum | J69: Fabaceae | K69: Fabales | L69: Herbaceous | M69: 60,61, 62 | N69: OT-031
A70: 68 | B70: 46048 | C70: Genbank | D70: 28 | E70: F252579 | F70: CIAT789 | G70: Zornia | H70: latifolia | I70: Zornia latifolia | J70: Fabaceae | K70: Fabales | L70: Herbaceous | M70: 60,61, 62 | N70: OT-031
A71: 69 | B71: 46048 | C71: Genbank | D71: 28 | E71: F252580 | F71: CIAT2085 | G71: Stylosanthes | H71: seabrana | I71: Stylosanthes seabrana | J71: Fabaceae | K71: Fabales | L71: Herbaceous | M71: 60,61, 62 | N71: OT-031
A72: 70 | B72: 46048 | C72: Genbank | D72: 28 | E72: F252581 | F72: CIAT2690 | G72: Stylosanthes | H72: angustifolia | I72: Stylosanthes angustifolia | J72: Fabaceae | K72: Fabales | L72: Herbaceous | M72: 60,61, 62 | N72: OT-031
A73: 71 | B73: 46048 | C73: Genbank | D73: 28 | E73: F252582 | F73: CIAT4069 | G73: Macroptilium | H73: atropurpureum | I73: Macroptilium atropurpureum | J73: Fabaceae | K73: Fabales | L73: Herbaceous | M73: 60,61, 62 | N73: OT-031
A74: 72 | B74: 46048 | C74: Genbank | D74: 28 | E74: F252583 | F74: CIAT4141 | G74: Vigna | H74: radiata | I74: Vigna radiata | J74: Fabaceae | K74: Fabales | L74: Herbaceous | M74: 60,61, 62 | N74: OT-031
...

Sheet 2.1. DM
B10: No | C10: Date | D10: ='1. Information samples'!D10 -> Requisitioner | E10: ='1. Information samples'!E10 -> Set CIAT | F10: ='1. Information samples'!F10 -> CIAT Lab-ID | G10: ='1. Information samples'!G10 -> Gene bank /Breeding program ID | H10: ='1. Information samples'!H10 -> Genus | I10: ='1. Information samples'!I10 -> Species | J10: ='1. Information samples'!J10 -> Tax Name | K10: ='1. Information samples'!K10 -> Family | ... O10: ='1. Information samples'!O10 -> ID LAB | P10: DM, % | Q10: Av DM 105 | R10: Ash, % | S10: Av Ash, % | T10: OM, % | U10: OM, %
B11: 1 | C11: ='1. Information samples'!C11 -> 46041 | D11: ='1. Information samples'!D11 -> Genbank | E11: ='1. Information samples'!E11 -> 27 | F11: ='1. Information samples'!F11 -> F251728 | G11: ='1. Information samples'!G11 -> CIAT-13262 | H11: ='1. Information samples'!H11 -> Dendrolobium | I11: ='1. Information samples'!I11 -> triangulare | J11: ='1. Information samples'!J11 -> Dendrolobium triangulare | ... O11: ='1. Information samples'!O11 -> OT-010 (2025) | P11: 94.902549 | Q11: =AVERAGE(P11:P12) -> 94.932282 | R11: 8.6755336 | S11: =AVERAGE(R11:R12) -> 8.6970265 | T11: 91.324466 | U11: =AVERAGE(T11:T12) -> 91.302974
B12: =B11+1 -> 2 | C12: =C11 -> 46041 | D12: =D11 -> Genbank | E12: =E11 -> 27 | F12: =F11 -> F251728 | G12: =G11 -> CIAT-13262 | H12: =H11 -> Dendrolobium | I12: =I11 -> triangulare | J12: =J11 -> Dendrolobium triangulare | ... O12: =O11 -> OT-010 (2025) | P12: 94.962015 | R12: 8.7185193 | T12: 91.281481
B13: =B12+1 -> 3 | C13: ='1. Information samples'!C12 -> 46041 | D13: ='1. Information samples'!D12 -> Genbank | E13: ='1. Information samples'!E12 -> 27 | F13: ='1. Information samples'!F12 -> F251729 | G13: ='1. Information samples'!G12 -> CIAT-13528 | H13: ='1. Information samples'!H12 -> Dendrolobium | I13: ='1. Information samples'!I12 -> lanceolatum | J13: ='1. Information samples'!J12 -> Dendrolobium lanceolatum | ... O13: ='1. Information samples'!O12 -> OT-010 (2025) | P13: 95.0005 | Q13: =AVERAGE(P13:P14) -> 95.045741 | R13: 7.5850627 | S13: =AVERAGE(R13:R14) -> 7.5846836 | T13: 92.414937 | U13: =AVERAGE(T13:T14) -> 92.415316
B14: =B13+1 -> 4 | C14: =C13 -> 46041 | D14: =D13 -> Genbank | E14: =E13 -> 27 | F14: =F13 -> F251729 | G14: =G13 -> CIAT-13528 | H14: =H13 -> Dendrolobium | I14: =I13 -> lanceolatum | J14: =J13 -> Dendrolobium lanceolatum | ... O14: =O13 -> OT-010 (2025) | P14: 95.090982 | R14: 7.5843044 | T14: 92.415696
B15: =B14+1 -> 5 | C15: ='1. Information samples'!C13 -> 46041 | D15: ='1. Information samples'!D13 -> Genbank | E15: ='1. Information samples'!E13 -> 27 | F15: ='1. Information samples'!F13 -> F251730 | G15: ='1. Information samples'!G13 -> CIAT-13529 | H15: ='1. Information samples'!H13 -> Dendrolobium | I15: ='1. Information samples'!I13 -> triangulare | J15: ='1. Information samples'!J13 -> Dendrolobium triangulare | ... O15: ='1. Information samples'!O13 -> OT-010 (2025) | P15: 94.302849 | Q15: =AVERAGE(P15:P16) -> 94.356983 | R15: 6.7158056 | S15: =AVERAGE(R15:R16) -> 6.690323 | T15: 93.284194 | U15: =AVERAGE(T15:T16) -> 93.309677
B16: =B15+1 -> 6 | C16: =C15 -> 46041 | D16: =D15 -> Genbank | E16: =E15 -> 27 | F16: =F15 -> F251730 | G16: =G15 -> CIAT-13529 | H16: =H15 -> Dendrolobium | I16: =I15 -> triangulare | J16: =J15 -> Dendrolobium triangulare | ... O16: =O15 -> OT-010 (2025) | P16: 94.411118 | R16: 6.6648403 | T16: 93.33516
B17: =B16+1 -> 7 | C17: ='1. Information samples'!C14 -> 46041 | D17: ='1. Information samples'!D14 -> Genbank | E17: ='1. Information samples'!E14 -> 27 | F17: ='1. Information samples'!F14 -> F251731 | G17: ='1. Information samples'!G14 -> CIAT-13710 | H17: ='1. Information samples'!H14 -> Dendrolobium | I17: ='1. Information samples'!I14 -> lanceolatum | J17: ='1. Information samples'!J14 -> Dendrolobium lanceolatum | ... O17: ='1. Information samples'!O14 -> OT-010 (2025) | P17: 94.092954 | Q17: =AVERAGE(P17:P18) -> 94.132642 | R17: 7.5493969 | S17: =AVERAGE(R17:R18) -> 7.4913694 | T17: 92.450603 | U17: =AVERAGE(T17:T18) -> 92.508631
B18: =B17+1 -> 8 | C18: =C17 -> 46041 | D18: =D17 -> Genbank | E18: =E17 -> 27 | F18: =F17 -> F251731 | G18: =G17 -> CIAT-13710 | H18: =H17 -> Dendrolobium | I18: =I17 -> lanceolatum | J18: =J17 -> Dendrolobium lanceolatum | ... O18: =O17 -> OT-010 (2025) | P18: 94.172331 | R18: 7.4333419 | T18: 92.566658
B19: =B18+1 -> 9 | C19: ='1. Information samples'!C15 -> 46041 | D19: ='1. Information samples'!D15 -> Genbank | E19: ='1. Information samples'!E15 -> 27 | F19: ='1. Information samples'!F15 -> F251732 | G19: ='1. Information samples'!G15 -> CIAT-22004 | H19: ='1. Information samples'!H15 -> Dendrolobium | I19: ='1. Information samples'!I15 -> triangulare | J19: ='1. Information samples'!J15 -> Dendrolobium triangulare | ... O19: ='1. Information samples'!O15 -> OT-010 (2025) | P19: 94.180582 | Q19: =AVERAGE(P19:P20) -> 94.29585 | R19: 6.7864705 | S19: =AVERAGE(R19:R20) -> 6.8126383 | T19: 93.213529 | U19: =AVERAGE(T19:T20) -> 93.187362
B20: =B19+1 -> 10 | C20: =C19 -> 46041 | D20: =D19 -> Genbank | E20: =E19 -> 27 | F20: =F19 -> F251732 | G20: =G19 -> CIAT-22004 | H20: =H19 -> Dendrolobium | I20: =I19 -> triangulare | J20: =J19 -> Dendrolobium triangulare | ... O20: =O19 -> OT-010 (2025) | P20: 94.411118 | R20: 6.838806 | T20: 93.161194
B21: =B20+1 -> 11 | C21: ='1. Information samples'!C16 -> 46041 | D21: ='1. Information samples'!D16 -> Genbank | E21: ='1. Information samples'!E16 -> 27 | F21: ='1. Information samples'!F16 -> F251733 | G21: ='1. Information samples'!G16 -> CIAT-23104 | H21: ='1. Information samples'!H16 -> Dendrolobium | I21: ='1. Information samples'!I16 -> triangulare | J21: ='1. Information samples'!J16 -> Dendrolobium triangulare | ... O21: ='1. Information samples'!O16 -> OT-010 (2025) | P21: 92.622951 | Q21: =AVERAGE(P21:P22) -> 92.632579 | R21: 7.0357461 | S21: =AVERAGE(R21:R22) -> 6.9983254 | T21: 92.964254 | U21: =AVERAGE(T21:T22) -> 93.001675
B22: =B21+1 -> 12 | C22: =C21 -> 46041 | D22: =D21 -> Genbank | E22: =E21 -> 27 | F22: =F21 -> F251733 | G22: =G21 -> CIAT-23104 | H22: =H21 -> Dendrolobium | I22: =I21 -> triangulare | J22: =J21 -> Dendrolobium triangulare | ... O22: =O21 -> OT-010 (2025) | P22: 92.642207 | R22: 6.9609047 | T22: 93.039095
B23: =B22+1 -> 13 | C23: ='1. Information samples'!C17 -> 46041 | D23: ='1. Information samples'!D17 -> Genbank | E23: ='1. Information samples'!E17 -> 27 | F23: ='1. Information samples'!F17 -> F251734 | G23: ='1. Information samples'!G17 -> CIAT-23106 | H23: ='1. Information samples'!H17 -> Dendrolobium | I23: ='1. Information samples'!I17 -> triangulare | J23: ='1. Information samples'!J17 -> Dendrolobium triangulare | ... O23: ='1. Information samples'!O17 -> OT-010 (2025) | P23: 94.502749 | Q23: =AVERAGE(P23:P24) -> 94.652674 | R23: 6.8004224 | S23: =AVERAGE(R23:R24) -> 6.8532207 | T23: 93.199578 | U23: =AVERAGE(T23:T24) -> 93.146779
B24: =B23+1 -> 14 | C24: =C23 -> 46041 | D24: =D23 -> Genbank | E24: =E23 -> 27 | F24: =F23 -> F251734 | G24: =G23 -> CIAT-23106 | H24: =H23 -> Dendrolobium | I24: =I23 -> triangulare | J24: =J23 -> Dendrolobium triangulare | ... O24: =O23 -> OT-010 (2025) | P24: 94.802599 | R24: 6.906019 | T24: 93.093981
B25: =B24+1 -> 15 | C25: ='1. Information samples'!C18 -> 46041 | D25: ='1. Information samples'!D18 -> Genbank | E25: ='1. Information samples'!E18 -> 27 | F25: ='1. Information samples'!F18 -> F251735 | G25: ='1. Information samples'!G18 -> CIAT-23107 | H25: ='1. Information samples'!H18 -> Dendrolobium | I25: ='1. Information samples'!I18 -> triangulare | J25: ='1. Information samples'!J18 -> Dendrolobium triangulare | ... O25: ='1. Information samples'!O18 -> OT-010 (2025) | P25: 94.962519 | Q25: =AVERAGE(P25:P26) -> 94.987008 | R25: 6.8396213 | S25: =AVERAGE(R25:R26) -> 6.9192396 | T25: 93.160379 | U25: =AVERAGE(T25:T26) -> 93.08076
B26: =B25+1 -> 16 | C26: =C25 -> 46041 | D26: =D25 -> Genbank | E26: =E25 -> 27 | F26: =F25 -> F251735 | G26: =G25 -> CIAT-23107 | H26: =H25 -> Dendrolobium | I26: =I25 -> triangulare | J26: =J25 -> Dendrolobium triangulare | ... O26: =O25 -> OT-010 (2025) | P26: 95.011497 | R26: 6.9988578 | T26: 93.001142
B27: =B26+1 -> 17 | C27: ='1. Information samples'!C19 -> 46041 | D27: ='1. Information samples'!D19 -> Genbank | E27: ='1. Information samples'!E19 -> 27 | F27: ='1. Information samples'!F19 -> F251736 | G27: ='1. Information samples'!G19 -> CIAT-23108 | H27: ='1. Information samples'!H19 -> Dendrolobium | I27: ='1. Information samples'!I19 -> triangulare | J27: ='1. Information samples'!J19 -> Dendrolobium triangulare | ... O27: ='1. Information samples'!O19 -> OT-010 (2025) | P27: 94.473316 | Q27: =AVERAGE(P27:P28) -> 94.543274 | R27: 6.8710359 | S27: =AVERAGE(R27:R28) -> 6.9291755 | T27: 93.128964 | U27: =AVERAGE(T27:T28) -> 93.070825
B28: =B27+1 -> 18 | C28: =C27 -> 46041 | D28: =D27 -> Genbank | E28: =E27 -> 27 | F28: =F27 -> F251736 | G28: =G27 -> CIAT-23108 | H28: =H27 -> Dendrolobium | I28: =I27 -> triangulare | J28: =J27 -> Dendrolobium triangulare | ... O28: =O27 -> OT-010 (2025) | P28: 94.613232 | R28: 6.987315 | T28: 93.012685
B29: =B28+1 -> 19 | C29: ='1. Information samples'!C20 -> 46041 | D29: ='1. Information samples'!D20 -> Genbank | E29: ='1. Information samples'!E20 -> 27 | F29: ='1. Information samples'!F20 -> F251737 | G29: ='1. Information samples'!G20 -> CIAT-23412 | H29: ='1. Information samples'!H20 -> Dendrolobium | I29: ='1. Information samples'!I20 -> triangulare | J29: ='1. Information samples'!J20 -> Dendrolobium triangulare | ... O29: ='1. Information samples'!O20 -> OT-010 (2025) | P29: 94.381685 | Q29: =AVERAGE(P29:P30) -> 94.187645 | R29: 7.2386932 | S29: =AVERAGE(R29:R30) -> 7.2747456 | T29: 92.761307 | U29: =AVERAGE(T29:T30) -> 92.725254
B30: =B29+1 -> 20 | C30: =C29 -> 46041 | D30: =D29 -> Genbank | E30: =E29 -> 27 | F30: =F29 -> F251737 | G30: =G29 -> CIAT-23412 | H30: =H29 -> Dendrolobium | I30: =I29 -> triangulare | J30: =J29 -> Dendrolobium triangulare | ... O30: =O29 -> OT-010 (2025) | P30: 93.993604 | R30: 7.310798 | T30: 92.689202
B31: =B30+1 -> 21 | C31: ='1. Information samples'!C21 -> 46041 | D31: ='1. Information samples'!D21 -> Genbank | E31: ='1. Information samples'!E21 -> 27 | F31: ='1. Information samples'!F21 -> F251738 | G31: ='1. Information samples'!G21 -> CIAT-23413 | H31: ='1. Information samples'!H21 -> Dendrolobium | I31: ='1. Information samples'!I21 -> triangulare | J31: ='1. Information samples'!J21 -> Dendrolobium triangulare | ... O31: ='1. Information samples'!O21 -> OT-010 (2025) | P31: 93.172731 | Q31: =AVERAGE(P31:P32) -> 93.526671 | R31: 7.5028791 | S31: =AVERAGE(R31:R32) -> 7.4986589 | T31: 92.497121 | U31: =AVERAGE(T31:T32) -> 92.501341
B32: =B31+1 -> 22 | C32: =C31 -> 46041 | D32: =D31 -> Genbank | E32: =E31 -> 27 | F32: =F31 -> F251738 | G32: =G31 -> CIAT-23413 | H32: =H31 -> Dendrolobium | I32: =I31 -> triangulare | J32: =J31 -> Dendrolobium triangulare | ... O32: =O31 -> OT-010 (2025) | P32: 93.880612 | R32: 7.4944387 | T32: 92.505561
B33: =B32+1 -> 23 | C33: ='1. Information samples'!C22 -> 46041 | D33: ='1. Information samples'!D22 -> Genbank | E33: ='1. Information samples'!E22 -> 27 | F33: ='1. Information samples'!F22 -> F251739 | G33: ='1. Information samples'!G22 -> CIAT-23419 | H33: ='1. Information samples'!H22 -> Dendrolobium | I33: ='1. Information samples'!I22 -> triangulare | J33: ='1. Information samples'!J22 -> Dendrolobium triangulare | ... O33: ='1. Information samples'!O22 -> OT-010 (2025) | P33: 93.813093 | Q33: =AVERAGE(P33:P34) -> 93.957431 | R33: 7.2230654 | S33: =AVERAGE(R33:R34) -> 7.2025076 | T33: 92.776935 | U33: =AVERAGE(T33:T34) -> 92.797492
B34: =B33+1 -> 24 | C34: =C33 -> 46041 | D34: =D33 -> Genbank | E34: =E33 -> 27 | F34: =F33 -> F251739 | G34: =G33 -> CIAT-23419 | H34: =H33 -> Dendrolobium | I34: =I33 -> triangulare | J34: =J33 -> Dendrolobium triangulare | ... O34: =O33 -> OT-010 (2025) | P34: 94.101769 | R34: 7.1819498 | T34: 92.81805
B35: =B34+1 -> 25 | C35: ='1. Information samples'!C23 -> 46041 | D35: ='1. Information samples'!D23 -> Genbank | E35: ='1. Information samples'!E23 -> 27 | F35: ='1. Information samples'!F23 -> F251740 | G35: ='1. Information samples'!G23 -> CIAT-23422 | H35: ='1. Information samples'!H23 -> Dendrolobium | I35: ='1. Information samples'!I23 -> triangulare | J35: ='1. Information samples'!J23 -> Dendrolobium triangulare | ... O35: ='1. Information samples'!O23 -> OT-010 (2025) | P35: 91.793283 | Q35: =AVERAGE(P35:P36) -> 91.857449 | R35: 7.0842344 | S35: =AVERAGE(R35:R36) -> 7.0631742 | T35: 92.915766 | U35: =AVERAGE(T35:T36) -> 92.936826
B36: =B35+1 -> 26 | C36: =C35 -> 46041 | D36: =D35 -> Genbank | E36: =E35 -> 27 | F36: =F35 -> F251740 | G36: =G35 -> CIAT-23422 | H36: =H35 -> Dendrolobium | I36: =I35 -> triangulare | J36: =J35 -> Dendrolobium triangulare | ... O36: =O35 -> OT-010 (2025) | P36: 91.921616 | R36: 7.042114 | T36: 92.957886
B37: =B36+1 -> 27 | C37: ='1. Information samples'!C24 -> 46041 | D37: ='1. Information samples'!D24 -> Genbank | E37: ='1. Information samples'!E24 -> 27 | F37: ='1. Information samples'!F24 -> F251741 | G37: ='1. Information samples'!G24 -> CIAT-23734 | H37: ='1. Information samples'!H24 -> Dendrolobium | I37: ='1. Information samples'!I24 -> triangulare | J37: ='1. Information samples'!J24 -> Dendrolobium triangulare | ... O37: ='1. Information samples'!O24 -> OT-010 (2025) | P37: 94.630537 | Q37: =AVERAGE(P37:P38) -> 94.71105 | R37: 7.8441292 | S37: =AVERAGE(R37:R38) -> 7.8591779 | T37: 92.155871 | U37: =AVERAGE(T37:T38) -> 92.140822
B38: =B37+1 -> 28 | C38: =C37 -> 46041 | D38: =D37 -> Genbank | E38: =E37 -> 27 | F38: =F37 -> F251741 | G38: =G37 -> CIAT-23734 | H38: =H37 -> Dendrolobium | I38: =I37 -> triangulare | J38: =J37 -> Dendrolobium triangulare | ... O38: =O37 -> OT-010 (2025) | P38: 94.791563 | R38: 7.8742266 | T38: 92.125773
B39: =B38+1 -> 29 | C39: ='1. Information samples'!C25 -> 46041 | D39: ='1. Information samples'!D25 -> Genbank | E39: ='1. Information samples'!E25 -> 27 | F39: ='1. Information samples'!F25 -> F251742 | G39: ='1. Information samples'!G25 -> CIAT-23932 | H39: ='1. Information samples'!H25 -> Dendrolobium | I39: ='1. Information samples'!I25 -> triangulare | J39: ='1. Information samples'!J25 -> Dendrolobium triangulare | ... O39: ='1. Information samples'!O25 -> OT-010 (2025) | P39: 95.121951 | Q39: =AVERAGE(P39:P40) -> 95.121951 | R39: 7.2929802 | S39: =AVERAGE(R39:R40) -> 7.2929802 | T39: 92.70702 | U39: =AVERAGE(T39:T40) -> 92.70702
B40: =B39+1 -> 30 | C40: =C39 -> 46041 | D40: =D39 -> Genbank | E40: =E39 -> 27 | F40: =F39 -> F251742 | G40: =G39 -> CIAT-23932 | H40: =H39 -> Dendrolobium | I40: =I39 -> triangulare | J40: =J39 -> Dendrolobium triangulare | ... O40: =O39 -> OT-010 (2025) | P40: 95.121951 | R40: 7.2929802 | T40: 92.70702
B41: =B40+1 -> 31 | C41: ='1. Information samples'!C26 -> 46041 | D41: ='1. Information samples'!D26 -> Genbank | E41: ='1. Information samples'!E26 -> 27 | F41: ='1. Information samples'!F26 -> F251743 | G41: ='1. Information samples'!G26 -> CIAT-23933 | H41: ='1. Information samples'!H26 -> Dendrolobium | I41: ='1. Information samples'!I26 -> triangulare | J41: ='1. Information samples'!J26 -> Dendrolobium triangulare | ... O41: ='1. Information samples'!O26 -> OT-010 (2025) | P41: 93.640636 | Q41: =AVERAGE(P41:P42) -> 93.721248 | R41: 7.3295152 | S41: =AVERAGE(R41:R42) -> 7.3714494 | T41: 92.670485 | U41: =AVERAGE(T41:T42) -> 92.628551
B42: =B41+1 -> 32 | C42: =C41 -> 46041 | D42: =D41 -> Genbank | E42: =E41 -> 27 | F42: =F41 -> F251743 | G42: =G41 -> CIAT-23933 | H42: =H41 -> Dendrolobium | I42: =I41 -> triangulare | J42: =J41 -> Dendrolobium triangulare | ... O42: =O41 -> OT-010 (2025) | P42: 93.801859 | R42: 7.4133836 | T42: 92.586616
B43: =B42+1 -> 33 | C43: ='1. Information samples'!C27 -> 46041 | D43: ='1. Information samples'!D27 -> Genbank | E43: ='1. Information samples'!E27 -> 27 | F43: ='1. Information samples'!F27 -> F251744 | G43: ='1. Information samples'!G27 -> CIAT-23934 | H43: ='1. Information samples'!H27 -> Dendrolobium | I43: ='1. Information samples'!I27 -> triangulare | J43: ='1. Information samples'!J27 -> Dendrolobium triangulare | ... O43: ='1. Information samples'!O27 -> OT-010 (2025) | P43: 94.13352 | Q43: =AVERAGE(P43:P44) -> 94.17176 | R43: 8.1610334 | S43: =AVERAGE(R43:R44) -> 8.1953384 | T43: 91.838967 | U43: =AVERAGE(T43:T44) -> 91.804662
B44: =B43+1 -> 34 | C44: =C43 -> 46041 | D44: =D43 -> Genbank | E44: =E43 -> 27 | F44: =F43 -> F251744 | G44: =G43 -> CIAT-23934 | H44: =H43 -> Dendrolobium | I44: =I43 -> triangulare | J44: =J43 -> Dendrolobium triangulare | ... O44: =O43 -> OT-010 (2025) | P44: 94.21 | R44: 8.2296434 | T44: 91.770357
B45: =B44+1 -> 35 | C45: ='1. Information samples'!C28 -> 46041 | D45: ='1. Information samples'!D28 -> Genbank | E45: ='1. Information samples'!E28 -> 27 | F45: ='1. Information samples'!F28 -> F251745 | G45: ='1. Information samples'!G28 -> CIAT-23936 | H45: ='1. Information samples'!H28 -> Dendrolobium | I45: ='1. Information samples'!I28 -> triangulare | J45: ='1. Information samples'!J28 -> Dendrolobium triangulare | ... O45: ='1. Information samples'!O28 -> OT-010 (2025) | P45: 94.063562 | Q45: =AVERAGE(P45:P46) -> 94.058565 | R45: 7.7458429 | S45: =AVERAGE(R45:R46) -> 7.7989693 | T45: 92.254157 | U45: =AVERAGE(T45:T46) -> 92.201031
B46: =B45+1 -> 36 | C46: =C45 -> 46041 | D46: =D45 -> Genbank | E46: =E45 -> 27 | F46: =F45 -> F251745 | G46: =G45 -> CIAT-23936 | H46: =H45 -> Dendrolobium | I46: =I45 -> triangulare | J46: =J45 -> Dendrolobium triangulare | ... O46: =O45 -> OT-010 (2025) | P46: 94.053568 | R46: 7.8520958 | T46: 92.147904
B47: =B46+1 -> 37 | C47: ='1. Information samples'!C29 -> 46041 | D47: ='1. Information samples'!D29 -> Genbank | E47: ='1. Information samples'!E29 -> 27 | F47: ='1. Information samples'!F29 -> F251746 | G47: ='1. Information samples'!G29 -> CIAT-33119 | H47: ='1. Information samples'!H29 -> Dendrolobium | I47: ='1. Information samples'!I29 -> triangulare | J47: ='1. Information samples'!J29 -> Dendrolobium triangulare | ... O47: ='1. Information samples'!O29 -> OT-010 (2025) | P47: 95.211437 | Q47: =AVERAGE(P47:P48) -> 95.287109 | R47: 7.4279477 | S47: =AVERAGE(R47:R48) -> 7.3953692 | T47: 92.572052 | U47: =AVERAGE(T47:T48) -> 92.604631
B48: =B47+1 -> 38 | C48: =C47 -> 46041 | D48: =D47 -> Genbank | E48: =E47 -> 27 | F48: =F47 -> F251746 | G48: =G47 -> CIAT-33119 | H48: =H47 -> Dendrolobium | I48: =I47 -> triangulare | J48: =J47 -> Dendrolobium triangulare | ... O48: =O47 -> OT-010 (2025) | P48: 95.362782 | R48: 7.3627908 | T48: 92.637209
B49: =B48+1 -> 39 | C49: ='1. Information samples'!C30 -> 46041 | D49: ='1. Information samples'!D30 -> Genbank | E49: ='1. Information samples'!E30 -> 27 | F49: ='1. Information samples'!F30 -> F251747 | G49: ='1. Information samples'!G30 -> CIAT-33383 | H49: ='1. Information samples'!H30 -> Dendrolobium | I49: ='1. Information samples'!I30 -> sp. | J49: ='1. Information samples'!J30 -> Dendrolobium sp. | ... O49: ='1. Information samples'!O30 -> OT-010 (2025) | P49: 94.55 | Q49: =AVERAGE(P49:P50) -> 94.671562 | R49: 9.5699277 | S49: =AVERAGE(R49:R50) -> 9.8045797 | T49: 90.430072 | U49: =AVERAGE(T49:T50) -> 90.19542
...

Sheet 2.2 Protein
P4: PROTEIN
B10: No | C10: Date | D10: Requisitioner | E10: Set CIAT | F10: CIAT Lab-ID | G10: Gene bank /Breeding program ID | H10: Genus | I10: Species | J10: Tax Name | K10: Family | L10: Order | M10: Functional Group | N10: Batches CIAT | O10: ID LAB | P10: Replication | Q10: Av DM 105 | R10: Av PC, %
B11: ='2.1. DM'!B11 -> 1 | C11: ='2.1. DM'!C11 -> 46041 | D11: ='2.1. DM'!D11 -> Genbank | E11: ='2.1. DM'!E11 -> 27 | F11: ='2.1. DM'!F11 -> F251728 | G11: ='2.1. DM'!G11 -> CIAT-13262 | H11: ='2.1. DM'!H11 -> Dendrolobium | I11: ='2.1. DM'!I11 -> triangulare | ... O11: ='2.1. DM'!O11 -> OT-010 (2025) | Q11: 18.980951 | R11: =AVERAGE(Q11:Q12) -> 18.980951
B12: ='2.1. DM'!B12 -> 2 | C12: ='2.1. DM'!C12 -> 46041 | D12: ='2.1. DM'!D12 -> Genbank | E12: ='2.1. DM'!E12 -> 27 | F12: ='2.1. DM'!F12 -> F251728 | G12: ='2.1. DM'!G12 -> CIAT-13262 | H12: ='2.1. DM'!H12 -> Dendrolobium | I12: ='2.1. DM'!I12 -> triangulare | ... O12: ='2.1. DM'!O12 -> OT-010 (2025) | Q12: 18.980951
B13: ='2.1. DM'!B13 -> 3 | C13: ='2.1. DM'!C13 -> 46041 | D13: ='2.1. DM'!D13 -> Genbank | E13: ='2.1. DM'!E13 -> 27 | F13: ='2.1. DM'!F13 -> F251729 | G13: ='2.1. DM'!G13 -> CIAT-13528 | H13: ='2.1. DM'!H13 -> Dendrolobium | I13: ='2.1. DM'!I13 -> lanceolatum | ... O13: ='2.1. DM'!O13 -> OT-010 (2025) | Q13: 16.897002 | R13: =AVERAGE(Q13:Q14) -> 16.897002
B14: ='2.1. DM'!B14 -> 4 | C14: ='2.1. DM'!C14 -> 46041 | D14: ='2.1. DM'!D14 -> Genbank | E14: ='2.1. DM'!E14 -> 27 | F14: ='2.1. DM'!F14 -> F251729 | G14: ='2.1. DM'!G14 -> CIAT-13528 | H14: ='2.1. DM'!H14 -> Dendrolobium | I14: ='2.1. DM'!I14 -> lanceolatum | ... O14: ='2.1. DM'!O14 -> OT-010 (2025) | Q14: 16.897002
B15: ='2.1. DM'!B15 -> 5 | C15: ='2.1. DM'!C15 -> 46041 | D15: ='2.1. DM'!D15 -> Genbank | E15: ='2.1. DM'!E15 -> 27 | F15: ='2.1. DM'!F15 -> F251730 | G15: ='2.1. DM'!G15 -> CIAT-13529 | H15: ='2.1. DM'!H15 -> Dendrolobium | I15: ='2.1. DM'!I15 -> triangulare | ... O15: ='2.1. DM'!O15 -> OT-010 (2025) | Q15: 18.170976 | R15: =AVERAGE(Q15:Q16) -> 18.170976
B16: ='2.1. DM'!B16 -> 6 | C16: ='2.1. DM'!C16 -> 46041 | D16: ='2.1. DM'!D16 -> Genbank | E16: ='2.1. DM'!E16 -> 27 | F16: ='2.1. DM'!F16 -> F251730 | G16: ='2.1. DM'!G16 -> CIAT-13529 | H16: ='2.1. DM'!H16 -> Dendrolobium | I16: ='2.1. DM'!I16 -> triangulare | ... O16: ='2.1. DM'!O16 -> OT-010 (2025) | Q16: 18.170976
B17: ='2.1. DM'!B17 -> 7 | C17: ='2.1. DM'!C17 -> 46041 | D17: ='2.1. DM'!D17 -> Genbank | E17: ='2.1. DM'!E17 -> 27 | F17: ='2.1. DM'!F17 -> F251731 | G17: ='2.1. DM'!G17 -> CIAT-13710 | H17: ='2.1. DM'!H17 -> Dendrolobium | I17: ='2.1. DM'!I17 -> lanceolatum | ... O17: ='2.1. DM'!O17 -> OT-010 (2025) | Q17: 19.138188 | R17: =AVERAGE(Q17:Q18) -> 19.138188
B18: ='2.1. DM'!B18 -> 8 | C18: ='2.1. DM'!C18 -> 46041 | D18: ='2.1. DM'!D18 -> Genbank | E18: ='2.1. DM'!E18 -> 27 | F18: ='2.1. DM'!F18 -> F251731 | G18: ='2.1. DM'!G18 -> CIAT-13710 | H18: ='2.1. DM'!H18 -> Dendrolobium | I18: ='2.1. DM'!I18 -> lanceolatum | ... O18: ='2.1. DM'!O18 -> OT-010 (2025) | Q18: 19.138188
B19: ='2.1. DM'!B19 -> 9 | C19: ='2.1. DM'!C19 -> 46041 | D19: ='2.1. DM'!D19 -> Genbank | E19: ='2.1. DM'!E19 -> 27 | F19: ='2.1. DM'!F19 -> F251732 | G19: ='2.1. DM'!G19 -> CIAT-22004 | H19: ='2.1. DM'!H19 -> Dendrolobium | I19: ='2.1. DM'!I19 -> triangulare | ... O19: ='2.1. DM'!O19 -> OT-010 (2025) | Q19: 17.58228 | R19: =AVERAGE(Q19:Q20) -> 17.58228
B20: ='2.1. DM'!B20 -> 10 | C20: ='2.1. DM'!C20 -> 46041 | D20: ='2.1. DM'!D20 -> Genbank | E20: ='2.1. DM'!E20 -> 27 | F20: ='2.1. DM'!F20 -> F251732 | G20: ='2.1. DM'!G20 -> CIAT-22004 | H20: ='2.1. DM'!H20 -> Dendrolobium | I20: ='2.1. DM'!I20 -> triangulare | ... O20: ='2.1. DM'!O20 -> OT-010 (2025) | Q20: 17.58228
B21: ='2.1. DM'!B21 -> 11 | C21: ='2.1. DM'!C21 -> 46041 | D21: ='2.1. DM'!D21 -> Genbank | E21: ='2.1. DM'!E21 -> 27 | F21: ='2.1. DM'!F21 -> F251733 | G21: ='2.1. DM'!G21 -> CIAT-23104 | H21: ='2.1. DM'!H21 -> Dendrolobium | I21: ='2.1. DM'!I21 -> triangulare | ... O21: ='2.1. DM'!O21 -> OT-010 (2025) | Q21: 19.394716 | R21: =AVERAGE(Q21:Q22) -> 19.394716
B22: ='2.1. DM'!B22 -> 12 | C22: ='2.1. DM'!C22 -> 46041 | D22: ='2.1. DM'!D22 -> Genbank | E22: ='2.1. DM'!E22 -> 27 | F22: ='2.1. DM'!F22 -> F251733 | G22: ='2.1. DM'!G22 -> CIAT-23104 | H22: ='2.1. DM'!H22 -> Dendrolobium | I22: ='2.1. DM'!I22 -> triangulare | ... O22: ='2.1. DM'!O22 -> OT-010 (2025) | Q22: 19.394716
B23: ='2.1. DM'!B23 -> 13 | C23: ='2.1. DM'!C23 -> 46041 | D23: ='2.1. DM'!D23 -> Genbank | E23: ='2.1. DM'!E23 -> 27 | F23: ='2.1. DM'!F23 -> F251734 | G23: ='2.1. DM'!G23 -> CIAT-23106 | H23: ='2.1. DM'!H23 -> Dendrolobium | I23: ='2.1. DM'!I23 -> triangulare | ... O23: ='2.1. DM'!O23 -> OT-010 (2025) | Q23: 21.885309 | R23: =AVERAGE(Q23:Q24) -> 21.885309
B24: ='2.1. DM'!B24 -> 14 | C24: ='2.1. DM'!C24 -> 46041 | D24: ='2.1. DM'!D24 -> Genbank | E24: ='2.1. DM'!E24 -> 27 | F24: ='2.1. DM'!F24 -> F251734 | G24: ='2.1. DM'!G24 -> CIAT-23106 | H24: ='2.1. DM'!H24 -> Dendrolobium | I24: ='2.1. DM'!I24 -> triangulare | ... O24: ='2.1. DM'!O24 -> OT-010 (2025) | Q24: 21.885309
B25: ='2.1. DM'!B25 -> 15 | C25: ='2.1. DM'!C25 -> 46041 | D25: ='2.1. DM'!D25 -> Genbank | E25: ='2.1. DM'!E25 -> 27 | F25: ='2.1. DM'!F25 -> F251735 | G25: ='2.1. DM'!G25 -> CIAT-23107 | H25: ='2.1. DM'!H25 -> Dendrolobium | I25: ='2.1. DM'!I25 -> triangulare | ... O25: ='2.1. DM'!O25 -> OT-010 (2025) | Q25: 21.240817 | R25: =AVERAGE(Q25:Q26) -> 21.240817
B26: ='2.1. DM'!B26 -> 16 | C26: ='2.1. DM'!C26 -> 46041 | D26: ='2.1. DM'!D26 -> Genbank | E26: ='2.1. DM'!E26 -> 27 | F26: ='2.1. DM'!F26 -> F251735 | G26: ='2.1. DM'!G26 -> CIAT-23107 | H26: ='2.1. DM'!H26 -> Dendrolobium | I26: ='2.1. DM'!I26 -> triangulare | ... O26: ='2.1. DM'!O26 -> OT-010 (2025) | Q26: 21.240817
B27: ='2.1. DM'!B27 -> 17 | C27: ='2.1. DM'!C27 -> 46041 | D27: ='2.1. DM'!D27 -> Genbank | E27: ='2.1. DM'!E27 -> 27 | F27: ='2.1. DM'!F27 -> F251736 | G27: ='2.1. DM'!G27 -> CIAT-23108 | H27: ='2.1. DM'!H27 -> Dendrolobium | I27: ='2.1. DM'!I27 -> triangulare | ... O27: ='2.1. DM'!O27 -> OT-010 (2025) | Q27: 21.587331 | R27: =AVERAGE(Q27:Q28) -> 21.587331
B28: ='2.1. DM'!B28 -> 18 | C28: ='2.1. DM'!C28 -> 46041 | D28: ='2.1. DM'!D28 -> Genbank | E28: ='2.1. DM'!E28 -> 27 | F28: ='2.1. DM'!F28 -> F251736 | G28: ='2.1. DM'!G28 -> CIAT-23108 | H28: ='2.1. DM'!H28 -> Dendrolobium | I28: ='2.1. DM'!I28 -> triangulare | ... O28: ='2.1. DM'!O28 -> OT-010 (2025) | Q28: 21.587331
B29: ='2.1. DM'!B29 -> 19 | C29: ='2.1. DM'!C29 -> 46041 | D29: ='2.1. DM'!D29 -> Genbank | E29: ='2.1. DM'!E29 -> 27 | F29: ='2.1. DM'!F29 -> F251737 | G29: ='2.1. DM'!G29 -> CIAT-23412 | H29: ='2.1. DM'!H29 -> Dendrolobium | I29: ='2.1. DM'!I29 -> triangulare | ... O29: ='2.1. DM'!O29 -> OT-010 (2025) | Q29: 21.25981 | R29: =AVERAGE(Q29:Q30) -> 21.147143
B30: ='2.1. DM'!B30 -> 20 | C30: ='2.1. DM'!C30 -> 46041 | D30: ='2.1. DM'!D30 -> Genbank | E30: ='2.1. DM'!E30 -> 27 | F30: ='2.1. DM'!F30 -> F251737 | G30: ='2.1. DM'!G30 -> CIAT-23412 | H30: ='2.1. DM'!H30 -> Dendrolobium | I30: ='2.1. DM'!I30 -> triangulare | ... O30: ='2.1. DM'!O30 -> OT-010 (2025) | Q30: 21.034476
B31: ='2.1. DM'!B31 -> 21 | C31: ='2.1. DM'!C31 -> 46041 | D31: ='2.1. DM'!D31 -> Genbank | E31: ='2.1. DM'!E31 -> 27 | F31: ='2.1. DM'!F31 -> F251738 | G31: ='2.1. DM'!G31 -> CIAT-23413 | H31: ='2.1. DM'!H31 -> Dendrolobium | I31: ='2.1. DM'!I31 -> triangulare | ... O31: ='2.1. DM'!O31 -> OT-010 (2025) | Q31: 21.317526 | R31: =AVERAGE(Q31:Q32) -> 21.317526
B32: ='2.1. DM'!B32 -> 22 | C32: ='2.1. DM'!C32 -> 46041 | D32: ='2.1. DM'!D32 -> Genbank | E32: ='2.1. DM'!E32 -> 27 | F32: ='2.1. DM'!F32 -> F251738 | G32: ='2.1. DM'!G32 -> CIAT-23413 | H32: ='2.1. DM'!H32 -> Dendrolobium | I32: ='2.1. DM'!I32 -> triangulare | ... O32: ='2.1. DM'!O32 -> OT-010 (2025) | Q32: 21.317526
B33: ='2.1. DM'!B33 -> 23 | C33: ='2.1. DM'!C33 -> 46041 | D33: ='2.1. DM'!D33 -> Genbank | E33: ='2.1. DM'!E33 -> 27 | F33: ='2.1. DM'!F33 -> F251739 | G33: ='2.1. DM'!G33 -> CIAT-23419 | H33: ='2.1. DM'!H33 -> Dendrolobium | I33: ='2.1. DM'!I33 -> triangulare | ... O33: ='2.1. DM'!O33 -> OT-010 (2025) | Q33: 20.194918 | R33: =AVERAGE(Q33:Q34) -> 20.194918
B34: ='2.1. DM'!B34 -> 24 | C34: ='2.1. DM'!C34 -> 46041 | D34: ='2.1. DM'!D34 -> Genbank | E34: ='2.1. DM'!E34 -> 27 | F34: ='2.1. DM'!F34 -> F251739 | G34: ='2.1. DM'!G34 -> CIAT-23419 | H34: ='2.1. DM'!H34 -> Dendrolobium | I34: ='2.1. DM'!I34 -> triangulare | ... O34: ='2.1. DM'!O34 -> OT-010 (2025) | Q34: 20.194918
B35: ='2.1. DM'!B35 -> 25 | C35: ='2.1. DM'!C35 -> 46041 | D35: ='2.1. DM'!D35 -> Genbank | E35: ='2.1. DM'!E35 -> 27 | F35: ='2.1. DM'!F35 -> F251740 | G35: ='2.1. DM'!G35 -> CIAT-23422 | H35: ='2.1. DM'!H35 -> Dendrolobium | I35: ='2.1. DM'!I35 -> triangulare | ... O35: ='2.1. DM'!O35 -> OT-010 (2025) | Q35: 21.674954 | R35: =AVERAGE(Q35:Q36) -> 21.674954
B36: ='2.1. DM'!B36 -> 26 | C36: ='2.1. DM'!C36 -> 46041 | D36: ='2.1. DM'!D36 -> Genbank | E36: ='2.1. DM'!E36 -> 27 | F36: ='2.1. DM'!F36 -> F251740 | G36: ='2.1. DM'!G36 -> CIAT-23422 | H36: ='2.1. DM'!H36 -> Dendrolobium | I36: ='2.1. DM'!I36 -> triangulare | ... O36: ='2.1. DM'!O36 -> OT-010 (2025) | Q36: 21.674954
B37: ='2.1. DM'!B37 -> 27 | C37: ='2.1. DM'!C37 -> 46041 | D37: ='2.1. DM'!D37 -> Genbank | E37: ='2.1. DM'!E37 -> 27 | F37: ='2.1. DM'!F37 -> F251741 | G37: ='2.1. DM'!G37 -> CIAT-23734 | H37: ='2.1. DM'!H37 -> Dendrolobium | I37: ='2.1. DM'!I37 -> triangulare | ... O37: ='2.1. DM'!O37 -> OT-010 (2025) | Q37: 21.435014 | R37: =AVERAGE(Q37:Q38) -> 21.435014
B38: ='2.1. DM'!B38 -> 28 | C38: ='2.1. DM'!C38 -> 46041 | D38: ='2.1. DM'!D38 -> Genbank | E38: ='2.1. DM'!E38 -> 27 | F38: ='2.1. DM'!F38 -> F251741 | G38: ='2.1. DM'!G38 -> CIAT-23734 | H38: ='2.1. DM'!H38 -> Dendrolobium | I38: ='2.1. DM'!I38 -> triangulare | ... O38: ='2.1. DM'!O38 -> OT-010 (2025) | Q38: 21.435014
B39: ='2.1. DM'!B39 -> 29 | C39: ='2.1. DM'!C39 -> 46041 | D39: ='2.1. DM'!D39 -> Genbank | E39: ='2.1. DM'!E39 -> 27 | F39: ='2.1. DM'!F39 -> F251742 | G39: ='2.1. DM'!G39 -> CIAT-23932 | H39: ='2.1. DM'!H39 -> Dendrolobium | I39: ='2.1. DM'!I39 -> triangulare | ... O39: ='2.1. DM'!O39 -> OT-010 (2025) | Q39: 18.840827 | R39: =AVERAGE(Q39:Q40) -> 18.840827
B40: ='2.1. DM'!B40 -> 30 | C40: ='2.1. DM'!C40 -> 46041 | D40: ='2.1. DM'!D40 -> Genbank | E40: ='2.1. DM'!E40 -> 27 | F40: ='2.1. DM'!F40 -> F251742 | G40: ='2.1. DM'!G40 -> CIAT-23932 | H40: ='2.1. DM'!H40 -> Dendrolobium | I40: ='2.1. DM'!I40 -> triangulare | ... O40: ='2.1. DM'!O40 -> OT-010 (2025) | Q40: 18.840827
B41: ='2.1. DM'!B41 -> 31 | C41: ='2.1. DM'!C41 -> 46041 | D41: ='2.1. DM'!D41 -> Genbank | E41: ='2.1. DM'!E41 -> 27 | F41: ='2.1. DM'!F41 -> F251743 | G41: ='2.1. DM'!G41 -> CIAT-23933 | H41: ='2.1. DM'!H41 -> Dendrolobium | I41: ='2.1. DM'!I41 -> triangulare | ... O41: ='2.1. DM'!O41 -> OT-010 (2025) | Q41: 17.584206 | R41: =AVERAGE(Q41:Q42) -> 17.584206
B42: ='2.1. DM'!B42 -> 32 | C42: ='2.1. DM'!C42 -> 46041 | D42: ='2.1. DM'!D42 -> Genbank | E42: ='2.1. DM'!E42 -> 27 | F42: ='2.1. DM'!F42 -> F251743 | G42: ='2.1. DM'!G42 -> CIAT-23933 | H42: ='2.1. DM'!H42 -> Dendrolobium | I42: ='2.1. DM'!I42 -> triangulare | ... O42: ='2.1. DM'!O42 -> OT-010 (2025) | Q42: 17.584206
B43: ='2.1. DM'!B43 -> 33 | C43: ='2.1. DM'!C43 -> 46041 | D43: ='2.1. DM'!D43 -> Genbank | E43: ='2.1. DM'!E43 -> 27 | F43: ='2.1. DM'!F43 -> F251744 | G43: ='2.1. DM'!G43 -> CIAT-23934 | H43: ='2.1. DM'!H43 -> Dendrolobium | I43: ='2.1. DM'!I43 -> triangulare | ... O43: ='2.1. DM'!O43 -> OT-010 (2025) | Q43: 22.612796 | R43: =AVERAGE(Q43:Q44) -> 22.612796
B44: ='2.1. DM'!B44 -> 34 | C44: ='2.1. DM'!C44 -> 46041 | D44: ='2.1. DM'!D44 -> Genbank | E44: ='2.1. DM'!E44 -> 27 | F44: ='2.1. DM'!F44 -> F251744 | G44: ='2.1. DM'!G44 -> CIAT-23934 | H44: ='2.1. DM'!H44 -> Dendrolobium | I44: ='2.1. DM'!I44 -> triangulare | ... O44: ='2.1. DM'!O44 -> OT-010 (2025) | Q44: 22.612796
B45: ='2.1. DM'!B45 -> 35 | C45: ='2.1. DM'!C45 -> 46041 | D45: ='2.1. DM'!D45 -> Genbank | E45: ='2.1. DM'!E45 -> 27 | F45: ='2.1. DM'!F45 -> F251745 | G45: ='2.1. DM'!G45 -> CIAT-23936 | H45: ='2.1. DM'!H45 -> Dendrolobium | I45: ='2.1. DM'!I45 -> triangulare | ... O45: ='2.1. DM'!O45 -> OT-010 (2025) | Q45: 19.266313 | R45: =AVERAGE(Q45:Q46) -> 19.266313
B46: ='2.1. DM'!B46 -> 36 | C46: ='2.1. DM'!C46 -> 46041 | D46: ='2.1. DM'!D46 -> Genbank | E46: ='2.1. DM'!E46 -> 27 | F46: ='2.1. DM'!F46 -> F251745 | G46: ='2.1. DM'!G46 -> CIAT-23936 | H46: ='2.1. DM'!H46 -> Dendrolobium | I46: ='2.1. DM'!I46 -> triangulare | ... O46: ='2.1. DM'!O46 -> OT-010 (2025) | Q46: 19.266313
B47: ='2.1. DM'!B47 -> 37 | C47: ='2.1. DM'!C47 -> 46041 | D47: ='2.1. DM'!D47 -> Genbank | E47: ='2.1. DM'!E47 -> 27 | F47: ='2.1. DM'!F47 -> F251746 | G47: ='2.1. DM'!G47 -> CIAT-33119 | H47: ='2.1. DM'!H47 -> Dendrolobium | I47: ='2.1. DM'!I47 -> triangulare | ... O47: ='2.1. DM'!O47 -> OT-010 (2025) | Q47: 17.300431 | R47: =AVERAGE(Q47:Q48) -> 17.300431
B48: ='2.1. DM'!B48 -> 38 | C48: ='2.1. DM'!C48 -> 46041 | D48: ='2.1. DM'!D48 -> Genbank | E48: ='2.1. DM'!E48 -> 27 | F48: ='2.1. DM'!F48 -> F251746 | G48: ='2.1. DM'!G48 -> CIAT-33119 | H48: ='2.1. DM'!H48 -> Dendrolobium | I48: ='2.1. DM'!I48 -> triangulare | ... O48: ='2.1. DM'!O48 -> OT-010 (2025) | Q48: 17.300431
...

Sheet 2.3 ADF
P4: ACID DETERGENT FIBER
B10: No | C10: Date | D10: ='1. Information samples'!D10 -> Requisitioner | E10: ='1. Information samples'!E10 -> Set CIAT | F10: ='1. Information samples'!F10 -> CIAT Lab-ID | G10: ='1. Information samples'!G10 -> Gene bank /Breeding program ID | H10: ='1. Information samples'!H10 -> Genus | I10: ='1. Information samples'!I10 -> Species | J10: ='1. Information samples'!J10 -> Tax Name | K10: ='1. Information samples'!K10 -> Family | ... O10: ='1. Information samples'!O10 -> ID LAB | P10: Replication | Q10: ADF, % (DM) | R10: Av ADF, % (DM)
B11: ='2.1. DM'!B11 -> 1 | C11: ='2.1. DM'!C11 -> 46041 | D11: ='2.1. DM'!D11 -> Genbank | E11: ='2.1. DM'!E11 -> 27 | F11: ='2.1. DM'!F11 -> F251728 | G11: ='2.1. DM'!G11 -> CIAT-13262 | H11: ='2.1. DM'!H11 -> Dendrolobium | I11: ='2.1. DM'!I11 -> triangulare | ... O11: ='2.1. DM'!O11 -> OT-010 (2025) | P11: A | Q11: 47.874993 | R11: =AVERAGE(Q11:Q12) -> 47.523177
B12: ='2.1. DM'!B12 -> 2 | C12: ='2.1. DM'!C12 -> 46041 | D12: ='2.1. DM'!D12 -> Genbank | E12: ='2.1. DM'!E12 -> 27 | F12: ='2.1. DM'!F12 -> F251728 | G12: ='2.1. DM'!G12 -> CIAT-13262 | H12: ='2.1. DM'!H12 -> Dendrolobium | I12: ='2.1. DM'!I12 -> triangulare | ... O12: ='2.1. DM'!O12 -> OT-010 (2025) | P12: B | Q12: 47.171361
B13: ='2.1. DM'!B13 -> 3 | C13: ='2.1. DM'!C13 -> 46041 | D13: ='2.1. DM'!D13 -> Genbank | E13: ='2.1. DM'!E13 -> 27 | F13: ='2.1. DM'!F13 -> F251729 | G13: ='2.1. DM'!G13 -> CIAT-13528 | H13: ='2.1. DM'!H13 -> Dendrolobium | I13: ='2.1. DM'!I13 -> lanceolatum | ... O13: ='2.1. DM'!O13 -> OT-010 (2025) | P13: A | Q13: 48.312754 | R13: =AVERAGE(Q13:Q14) -> 48.362187
B14: ='2.1. DM'!B14 -> 4 | C14: ='2.1. DM'!C14 -> 46041 | D14: ='2.1. DM'!D14 -> Genbank | E14: ='2.1. DM'!E14 -> 27 | F14: ='2.1. DM'!F14 -> F251729 | G14: ='2.1. DM'!G14 -> CIAT-13528 | H14: ='2.1. DM'!H14 -> Dendrolobium | I14: ='2.1. DM'!I14 -> lanceolatum | ... O14: ='2.1. DM'!O14 -> OT-010 (2025) | P14: B | Q14: 48.41162
B15: ='2.1. DM'!B15 -> 5 | C15: ='2.1. DM'!C15 -> 46041 | D15: ='2.1. DM'!D15 -> Genbank | E15: ='2.1. DM'!E15 -> 27 | F15: ='2.1. DM'!F15 -> F251730 | G15: ='2.1. DM'!G15 -> CIAT-13529 | H15: ='2.1. DM'!H15 -> Dendrolobium | I15: ='2.1. DM'!I15 -> triangulare | ... O15: ='2.1. DM'!O15 -> OT-010 (2025) | P15: A | Q15: 44.493066 | R15: =AVERAGE(Q15:Q16) -> 45.328121
B16: ='2.1. DM'!B16 -> 6 | C16: ='2.1. DM'!C16 -> 46041 | D16: ='2.1. DM'!D16 -> Genbank | E16: ='2.1. DM'!E16 -> 27 | F16: ='2.1. DM'!F16 -> F251730 | G16: ='2.1. DM'!G16 -> CIAT-13529 | H16: ='2.1. DM'!H16 -> Dendrolobium | I16: ='2.1. DM'!I16 -> triangulare | ... O16: ='2.1. DM'!O16 -> OT-010 (2025) | P16: B | Q16: 46.163177
B17: ='2.1. DM'!B17 -> 7 | C17: ='2.1. DM'!C17 -> 46041 | D17: ='2.1. DM'!D17 -> Genbank | E17: ='2.1. DM'!E17 -> 27 | F17: ='2.1. DM'!F17 -> F251731 | G17: ='2.1. DM'!G17 -> CIAT-13710 | H17: ='2.1. DM'!H17 -> Dendrolobium | I17: ='2.1. DM'!I17 -> lanceolatum | ... O17: ='2.1. DM'!O17 -> OT-010 (2025) | P17: A | Q17: 53.587567 | R17: =AVERAGE(Q17:Q18) -> 55.171777
B18: ='2.1. DM'!B18 -> 8 | C18: ='2.1. DM'!C18 -> 46041 | D18: ='2.1. DM'!D18 -> Genbank | E18: ='2.1. DM'!E18 -> 27 | F18: ='2.1. DM'!F18 -> F251731 | G18: ='2.1. DM'!G18 -> CIAT-13710 | H18: ='2.1. DM'!H18 -> Dendrolobium | I18: ='2.1. DM'!I18 -> lanceolatum | ... O18: ='2.1. DM'!O18 -> OT-010 (2025) | P18: B | Q18: 56.755987
B19: ='2.1. DM'!B19 -> 9 | C19: ='2.1. DM'!C19 -> 46041 | D19: ='2.1. DM'!D19 -> Genbank | E19: ='2.1. DM'!E19 -> 27 | F19: ='2.1. DM'!F19 -> F251732 | G19: ='2.1. DM'!G19 -> CIAT-22004 | H19: ='2.1. DM'!H19 -> Dendrolobium | I19: ='2.1. DM'!I19 -> triangulare | ... O19: ='2.1. DM'!O19 -> OT-010 (2025) | P19: A | Q19: 49.288703 | R19: =AVERAGE(Q19:Q20) -> 49.203135
B20: ='2.1. DM'!B20 -> 10 | C20: ='2.1. DM'!C20 -> 46041 | D20: ='2.1. DM'!D20 -> Genbank | E20: ='2.1. DM'!E20 -> 27 | F20: ='2.1. DM'!F20 -> F251732 | G20: ='2.1. DM'!G20 -> CIAT-22004 | H20: ='2.1. DM'!H20 -> Dendrolobium | I20: ='2.1. DM'!I20 -> triangulare | ... O20: ='2.1. DM'!O20 -> OT-010 (2025) | P20: B | Q20: 49.117567
B21: ='2.1. DM'!B21 -> 11 | C21: ='2.1. DM'!C21 -> 46041 | D21: ='2.1. DM'!D21 -> Genbank | E21: ='2.1. DM'!E21 -> 27 | F21: ='2.1. DM'!F21 -> F251733 | G21: ='2.1. DM'!G21 -> CIAT-23104 | H21: ='2.1. DM'!H21 -> Dendrolobium | I21: ='2.1. DM'!I21 -> triangulare | ... O21: ='2.1. DM'!O21 -> OT-010 (2025) | P21: A | Q21: 55.829591 | R21: =AVERAGE(Q21:Q22) -> 57.005039
B22: ='2.1. DM'!B22 -> 12 | C22: ='2.1. DM'!C22 -> 46041 | D22: ='2.1. DM'!D22 -> Genbank | E22: ='2.1. DM'!E22 -> 27 | F22: ='2.1. DM'!F22 -> F251733 | G22: ='2.1. DM'!G22 -> CIAT-23104 | H22: ='2.1. DM'!H22 -> Dendrolobium | I22: ='2.1. DM'!I22 -> triangulare | ... O22: ='2.1. DM'!O22 -> OT-010 (2025) | P22: B | Q22: 58.180487
B23: ='2.1. DM'!B23 -> 13 | C23: ='2.1. DM'!C23 -> 46041 | D23: ='2.1. DM'!D23 -> Genbank | E23: ='2.1. DM'!E23 -> 27 | F23: ='2.1. DM'!F23 -> F251734 | G23: ='2.1. DM'!G23 -> CIAT-23106 | H23: ='2.1. DM'!H23 -> Dendrolobium | I23: ='2.1. DM'!I23 -> triangulare | ... O23: ='2.1. DM'!O23 -> OT-010 (2025) | P23: A | Q23: 56.170696 | R23: =AVERAGE(Q23:Q24) -> 55.750985
B24: ='2.1. DM'!B24 -> 14 | C24: ='2.1. DM'!C24 -> 46041 | D24: ='2.1. DM'!D24 -> Genbank | E24: ='2.1. DM'!E24 -> 27 | F24: ='2.1. DM'!F24 -> F251734 | G24: ='2.1. DM'!G24 -> CIAT-23106 | H24: ='2.1. DM'!H24 -> Dendrolobium | I24: ='2.1. DM'!I24 -> triangulare | ... O24: ='2.1. DM'!O24 -> OT-010 (2025) | P24: B | Q24: 55.331274
B25: ='2.1. DM'!B25 -> 15 | C25: ='2.1. DM'!C25 -> 46041 | D25: ='2.1. DM'!D25 -> Genbank | E25: ='2.1. DM'!E25 -> 27 | F25: ='2.1. DM'!F25 -> F251735 | G25: ='2.1. DM'!G25 -> CIAT-23107 | H25: ='2.1. DM'!H25 -> Dendrolobium | I25: ='2.1. DM'!I25 -> triangulare | ... O25: ='2.1. DM'!O25 -> OT-010 (2025) | P25: A | Q25: 51.066966 | R25: =AVERAGE(Q25:Q26) -> 51.070862
B26: ='2.1. DM'!B26 -> 16 | C26: ='2.1. DM'!C26 -> 46041 | D26: ='2.1. DM'!D26 -> Genbank | E26: ='2.1. DM'!E26 -> 27 | F26: ='2.1. DM'!F26 -> F251735 | G26: ='2.1. DM'!G26 -> CIAT-23107 | H26: ='2.1. DM'!H26 -> Dendrolobium | I26: ='2.1. DM'!I26 -> triangulare | ... O26: ='2.1. DM'!O26 -> OT-010 (2025) | P26: B | Q26: 51.074758
B27: ='2.1. DM'!B27 -> 17 | C27: ='2.1. DM'!C27 -> 46041 | D27: ='2.1. DM'!D27 -> Genbank | E27: ='2.1. DM'!E27 -> 27 | F27: ='2.1. DM'!F27 -> F251736 | G27: ='2.1. DM'!G27 -> CIAT-23108 | H27: ='2.1. DM'!H27 -> Dendrolobium | I27: ='2.1. DM'!I27 -> triangulare | ... O27: ='2.1. DM'!O27 -> OT-010 (2025) | P27: A | Q27: 58.313248 | R27: =AVERAGE(Q27:Q28) -> 58.167411
B28: ='2.1. DM'!B28 -> 18 | C28: ='2.1. DM'!C28 -> 46041 | D28: ='2.1. DM'!D28 -> Genbank | E28: ='2.1. DM'!E28 -> 27 | F28: ='2.1. DM'!F28 -> F251736 | G28: ='2.1. DM'!G28 -> CIAT-23108 | H28: ='2.1. DM'!H28 -> Dendrolobium | I28: ='2.1. DM'!I28 -> triangulare | ... O28: ='2.1. DM'!O28 -> OT-010 (2025) | P28: B | Q28: 58.021575
B29: ='2.1. DM'!B29 -> 19 | C29: ='2.1. DM'!C29 -> 46041 | D29: ='2.1. DM'!D29 -> Genbank | E29: ='2.1. DM'!E29 -> 27 | F29: ='2.1. DM'!F29 -> F251737 | G29: ='2.1. DM'!G29 -> CIAT-23412 | H29: ='2.1. DM'!H29 -> Dendrolobium | I29: ='2.1. DM'!I29 -> triangulare | ... O29: ='2.1. DM'!O29 -> OT-010 (2025) | P29: A | Q29: 49.559883 | R29: =AVERAGE(Q29:Q30) -> 50.97707
B30: ='2.1. DM'!B30 -> 20 | C30: ='2.1. DM'!C30 -> 46041 | D30: ='2.1. DM'!D30 -> Genbank | E30: ='2.1. DM'!E30 -> 27 | F30: ='2.1. DM'!F30 -> F251737 | G30: ='2.1. DM'!G30 -> CIAT-23412 | H30: ='2.1. DM'!H30 -> Dendrolobium | I30: ='2.1. DM'!I30 -> triangulare | ... O30: ='2.1. DM'!O30 -> OT-010 (2025) | P30: B | Q30: 52.394257
B31: ='2.1. DM'!B31 -> 21 | C31: ='2.1. DM'!C31 -> 46041 | D31: ='2.1. DM'!D31 -> Genbank | E31: ='2.1. DM'!E31 -> 27 | F31: ='2.1. DM'!F31 -> F251738 | G31: ='2.1. DM'!G31 -> CIAT-23413 | H31: ='2.1. DM'!H31 -> Dendrolobium | I31: ='2.1. DM'!I31 -> triangulare | ... O31: ='2.1. DM'!O31 -> OT-010 (2025) | P31: A | Q31: 53.271333 | R31: =AVERAGE(Q31:Q32) -> 54.591147
B32: ='2.1. DM'!B32 -> 22 | C32: ='2.1. DM'!C32 -> 46041 | D32: ='2.1. DM'!D32 -> Genbank | E32: ='2.1. DM'!E32 -> 27 | F32: ='2.1. DM'!F32 -> F251738 | G32: ='2.1. DM'!G32 -> CIAT-23413 | H32: ='2.1. DM'!H32 -> Dendrolobium | I32: ='2.1. DM'!I32 -> triangulare | ... O32: ='2.1. DM'!O32 -> OT-010 (2025) | P32: B | Q32: 55.910961
B33: ='2.1. DM'!B33 -> 23 | C33: ='2.1. DM'!C33 -> 46041 | D33: ='2.1. DM'!D33 -> Genbank | E33: ='2.1. DM'!E33 -> 27 | F33: ='2.1. DM'!F33 -> F251739 | G33: ='2.1. DM'!G33 -> CIAT-23419 | H33: ='2.1. DM'!H33 -> Dendrolobium | I33: ='2.1. DM'!I33 -> triangulare | ... O33: ='2.1. DM'!O33 -> OT-010 (2025) | P33: A | Q33: 56.136356 | R33: =AVERAGE(Q33:Q34) -> 56.434424
